package com.java_core;
import java.util.Scanner;
public class Java_42_ExceptionHandeling {
    public static void main(String[] args) {
        int [] marks = new int[3];
        marks[0] = 7;
        marks[1] = 56;
        marks[2] = 6;
        Scanner sc = new Scanner(System.in);
        System.out.println("Enter the array index");
        int ind = sc.nextInt();

        System.out.println("Enter the number you want to divide the value with");
        int number = sc.nextInt();
        try{
            // Try block immediately exits to catch block when it finds a error. it doest execute next statements
            System.out.println("The value at array index entered is: " + marks[ind]);
            System.out.println("The value of array-value/number is: " + marks[ind]/number);
        }
        catch (ArithmeticException e){
            System.out.println("ArithmeticException occured!");
            System.out.println(e);
        }
        catch (ArrayIndexOutOfBoundsException e){
            System.out.println("ArrayIndexOutOfBoundsException occured!");
            System.out.println(e);
        }
        catch (Exception e){
            System.out.println("Some other exception occured!");
            System.out.println(e);
        }
    }
}
